<sdf version='1.9'>
  <model name='robot'>
    <link name='base_link'>
      <inertial>
        <pose>0.022267326732673232 0 0.088217821782178227 0 0 0</pose>
        <mass>1.01</mass>
        <inertia>
          <ixx>0.086987858745874613</ixx>
          <ixy>0</ixy>
          <ixz>-0.00031188118811881481</ixz>
          <iyy>0.024791076567656799</iyy>
          <iyz>0</iyz>
          <izz>0.10447028448844881</izz>
        </inertia>
      </inertial>
      <collision name='base_link_fixed_joint_lump__chassis_collision'>
        <pose>0.02399999999999999 0 0.090000000000000011 0 0 0</pose>
        <geometry>
          <box>
            <size>2 3 0.20000000000000001</size>
          </box>
        </geometry>
        <surface>
          <contact>
            <ode/>
          </contact>
          <friction>
            <ode/>
          </friction>
        </surface>
      </collision>
      <collision name='base_link_fixed_joint_lump__caster_wheel_collision_1'>
        <pose>-0.151 0 -0.090000000000000011 0 0 0</pose>
        <geometry>
          <sphere>
            <radius>0.01</radius>
          </sphere>
        </geometry>
        <surface>
          <contact>
            <ode/>
          </contact>
          <friction>
            <ode>
              <mu>0.001</mu>
              <mu2>0.001</mu2>
            </ode>
          </friction>
        </surface>
      </collision>
      <visual name='base_link_fixed_joint_lump__chassis_visual'>
        <pose>0.02399999999999999 0 0.090000000000000011 0 0 0</pose>
        <geometry>
          <box>
            <size>0.5 1 0.20000000000000001</size>
          </box>
        </geometry>
        <material>
          <script>
            <name>Gazebo/Orange</name>
            <uri>file://media/materials/scripts/gazebo.material</uri>
          </script>
          <diffuse>1 0.37500003 0.125 1</diffuse>
          <ambient>1 0.37500003 0.125 1</ambient>
        </material>
      </visual>
      <visual name='base_link_fixed_joint_lump__caster_wheel_visual_1'>
        <pose>-0.151 0 -0.090000000000000011 0 0 0</pose>
        <geometry>
          <sphere>
            <radius>0.01</radius>
          </sphere>
        </geometry>
        <material>
          <script>
            <name>Gazebo/White</name>
            <uri>file://media/materials/scripts/gazebo.material</uri>
          </script>
          <diffuse>1 1 1 1</diffuse>
          <ambient>0,5 0,5 0,5 0,5</ambient>
        </material>
      </visual>
    </link>
    <joint name='left_wheel_joint' type='revolute'>
      <pose relative_to='base_link'>0 0.5 0 -1.5707963267948959 0 0</pose>
      <parent>base_link</parent>
      <child>left_wheel</child>
      <axis>
        <xyz>0 0 1</xyz>
        <limit>
          <lower>-inf</lower>
          <upper>inf</upper>
        </limit>
        <dynamics>
          <spring_reference>0</spring_reference>
          <spring_stiffness>0</spring_stiffness>
        </dynamics>
      </axis>
    </joint>
    <link name='left_wheel'>
      <pose relative_to='left_wheel_joint'>0 0 0 0 0 0</pose>
      <inertial>
        <pose>0 0 0 0 0 0</pose>
        <mass>0.050000000000000003</mass>
        <inertia>
          <ixx>0.00012781666666666669</ixx>
          <ixy>0</ixy>
          <ixz>0</ixz>
          <iyy>0.00012781666666666669</iyy>
          <iyz>0</iyz>
          <izz>0.00025000000000000011</izz>
        </inertia>
      </inertial>
      <collision name='left_wheel_collision'>
        <pose>0 0 0 0 0 0</pose>
        <geometry>
          <sphere>
            <radius>0.10000000000000001</radius>
          </sphere>
        </geometry>
        <surface>
          <contact>
            <ode/>
          </contact>
          <friction>
            <ode/>
          </friction>
        </surface>
      </collision>
      <visual name='left_wheel_visual'>
        <pose>0 0 0 0 0 0</pose>
        <geometry>
          <cylinder>
            <length>0.025999999999999999</length>
            <radius>0.10000000000000001</radius>
          </cylinder>
        </geometry>
        <material>
          <script>
            <name>Gazebo/Blue</name>
            <uri>file://media/materials/scripts/gazebo.material</uri>
          </script>
          <diffuse>0.25 0.25 1 1</diffuse>
          <ambient>0.25 0.25 1 1</ambient>
        </material>
      </visual>
    </link>
    <joint name='right_wheel_joint' type='revolute'>
      <pose relative_to='base_link'>0 -0.5 0 1.5707963267948959 0 0</pose>
      <parent>base_link</parent>
      <child>right_wheel</child>
      <axis>
        <xyz>0 0 -1</xyz>
        <limit>
          <lower>-inf</lower>
          <upper>inf</upper>
        </limit>
        <dynamics>
          <spring_reference>0</spring_reference>
          <spring_stiffness>0</spring_stiffness>
        </dynamics>
      </axis>
    </joint>
    <link name='right_wheel'>
      <pose relative_to='right_wheel_joint'>0 0 0 0 0 0</pose>
      <inertial>
        <pose>0 0 0 0 0 0</pose>
        <mass>0.050000000000000003</mass>
        <inertia>
          <ixx>0.00012781666666666669</ixx>
          <ixy>0</ixy>
          <ixz>0</ixz>
          <iyy>0.00012781666666666669</iyy>
          <iyz>0</iyz>
          <izz>0.00025000000000000011</izz>
        </inertia>
      </inertial>
      <collision name='right_wheel_collision'>
        <pose>0 0 0 0 0 0</pose>
        <geometry>
          <sphere>
            <radius>0.10000000000000001</radius>
          </sphere>
        </geometry>
        <surface>
          <contact>
            <ode/>
          </contact>
          <friction>
            <ode/>
          </friction>
        </surface>
      </collision>
      <visual name='right_wheel_visual'>
        <pose>0 0 0 0 0 0</pose>
        <geometry>
          <cylinder>
            <length>0</length>
            <radius>0.10000000000000001</radius>
          </cylinder>
        </geometry>
        <material>
          <script>
            <name>Gazebo/Blue</name>
            <uri>file://media/materials/scripts/gazebo.material</uri>
          </script>
          <diffuse>0.25 0.25 1 1</diffuse>
          <ambient>0.25 0.25 1 1</ambient>
        </material>
      </visual>
    </link>
    <plugin name='gz::sim::systems::JointStatePublisher' filename='gz-sim-joint-state-publisher-system'/>
    <plugin name='gz::sim::systems::DiffDrive' filename='gz-sim-diff-drive-system'>
      <left_joint>left_wheel_joint</left_joint>
      <right_joint>right_wheel_joint</right_joint>
      <child_frame_id>robot/base_link</child_frame_id>
      <wheel_separation>0.291</wheel_separation>
      <wheel_radius>0.033</wheel_radius>
      <odom_publish_frequency>10</odom_publish_frequency>
    </plugin>
    <frame name='base_footprint_joint' attached_to='base_link'>
      <pose>0 0 -0.13800000000000001 0 0 0</pose>
    </frame>
    <frame name='base_footprint' attached_to='base_footprint_joint'>
      <pose>0 0 0 0 0 0</pose>
    </frame>
    <frame name='caster_wheel_joint' attached_to='chassis'>
      <pose>0.074999999999999997 0 -0.080000000000000016 0 0 0</pose>
    </frame>
    <frame name='caster_wheel' attached_to='caster_wheel_joint'>
      <pose>0 0 0 0 0 0</pose>
    </frame>
    <frame name='chassis_joint' attached_to='base_link'>
      <pose>-0.22600000000000001 0 -0.01 0 0 0</pose>
    </frame>
    <frame name='chassis' attached_to='chassis_joint'>
      <pose>0 0 0 0 0 0</pose>
    </frame>
  </model>
</sdf>
